Workbook

Sheet DH Grocery Items
A1: AHKF Monthly Stationery Stock Report Dhouk Hassu
A2: Month of April 2026
A3: Opening Stock | B3: Balance Stock | D3: Minimum Stock to be Kept | E3: Procurement Suggestion | F3: Stock IN | J3: Stock OUT
B4: Product Name | C4: Balance Quantity | F4: Date | G4: Product Name | H4: Quantity | I4: Status | J4: Date | K4: Product Name | L4: Quantity | M4: Status
A5: 4 | B5: Everyday Milk Powder(850 Grams) | C5: =A5 -> 4 | D5: 8 | E5: =IF(C5<D5,"Place Order","") -> Place Order | G5: Everyday Milk Powder(850 Grams) | H5: 2 | K5: Everyday Milk Powder(850 Grams) | L5: 2
A6: 0 | B6: White Sugar Kg | C6: 4 | D6: 5 | E6: =IF(C6<D6,"Place Order","") -> Place Order | G6: White Sugar Kg | H6: 5 | K6: White Sugar Kg | L6: 1
A7: =H7-L7 -> 0 | B7: Tea (Open)(500 Grams) Pkt | C7: =A7 -> 0 | D7: 1.5 | E7: =IF(C7<D7,"Place Order","") -> Place Order | G7: Tea (Open)(500 Grams) Pkt | H7: 1 | K7: Tea (Open)(500 Grams) Pkt | L7: 1
A8: 0 | B8: Green Tea (25 Bags) Pkt | C8: =A8 -> 0 | D8: 0 | E8: =IF(C8<D8,"Place Order","") | G8: Green Tea (25 Bags) Pkt | K8: Green Tea (25 Bags) Pkt
B12: ________________________ | G12: ________________________ | K12: ________________________
B13: Prepared By | G13: Checked By | K13: Reviewed By
B14: Atiqa Saeed | G14: Muhammad Saadat | K14: Zeeshan Nasar
B15: Admin Cum Program Assistant | G15: Sr. Admin Officer | K15: Operations Manager

Sheet DH Janitorial Items
A1: AHKF Monthly Stationery Stock Report Dhouk Hassu
A2: Month of April 2026
A3: Opening Stock | B3: Balance Stock | D3: Minimum Stock to be Kept | E3: Procurement Suggestion | F3: Stock IN | J3: Stock OUT
B4: Product Name | C4: Balance Quantity | F4: Date | G4: Product Name | H4: Quantity | I4: Status | J4: Date | K4: Product Name | L4: Quantity | M4: Status
A5: 0 | B5: Phynenyl (2.75 Lit) | C5: =A5+H5-L5 -> 1 | D5: 2 | E5: =IF(C5<D5,"Place Order","") -> Place Order | G5: Phynenyl (2.75 Lit) | H5: 2 | K5: Phynenyl (2.75 Lit) | L5: 1
A6: 0 | B6: Broom-Phool Jharoo | C6: =A6+H6-L6 -> 1 | D6: 1 | E6: =IF(C6<D6,"Place Order","") | G6: Broom-Phool Jharoo | H6: 2 | K6: Broom-Phool Jharoo | L6: 1
A7: 0 | B7: Broom-Jharoo (Bamboo) | C7: =H7-L7 -> 0 | D7: 0 | E7: =IF(C7<D7,"Place Order","") | G7: Broom-Jharoo (Bamboo) | H7: 0 | K7: Broom-Jharoo (Bamboo) | L7: 0
A8: 0 | B8: Brush Cleaning with Rode (Jala) | C8: =A8-L8 -> 0 | D8: 0 | E8: =IF(C8<D8,"Place Order","") | G8: Brush Cleaning with Rode (Jala) | H8: 0 | K8: Brush Cleaning with Rode (Jala) | L8: 0
A9: 0 | B9: Duster Cloth | C9: =A9+H9-L9 -> -1 | D9: 2 | E9: =IF(C9<D9,"Place Order","") -> Place Order | G9: Duster Cloth | H9: 0 | K9: Duster Cloth | L9: 1
A10: 0 | B10: Harpic (750 ml) bottle | C10: 1 | D10: 2 | E10: =IF(C10<D10,"Place Order","") -> Place Order | G10: Harpic (750 ml) bottle | H10: 2 | K10: Harpic (750 ml) bottle | L10: 1
A11: 0 | B11: Hand Washing Soap (Large size) | C11: =A11+H11-L11 -> 1 | D11: 4 | E11: =IF(C11<D11,"Place Order","") -> Place Order | G11: Hand Washing Soap (Large size) | H11: 2 | K11: Hand Washing Soap (Large size) | L11: 1
A12: 0 | B12: Hand Wash Liquid (1 Liter) | C12: =H12-L12 -> 0 | D12: 0 | E12: =IF(C12<D12,"Place Order","") | G12: Hand Wash Liquid (1 Liter) | H12: 0 | K12: Hand Wash Liquid (1 Liter) | L12: 0
A13: 0 | B13: Scotch Brite | C13: =H13-L13 -> 0 | D13: 0 | E13: =IF(C13<D13,"Place Order","") | G13: Scotch Brite | H13: 0 | K13: Scotch Brite | L13: 0
A14: 0 | B14: Lemon Max (275 ML) | C14: 1 | D14: 2 | E14: =IF(C14<D14,"Place Order","") -> Place Order | G14: Lemon Max (275 ML) | H14: 2 | K14: Lemon Max (275 ML) | L14: 1
A15: 0 | B15: Wiper (Large size) | C15: =A15+H15-L15 -> 0 | D15: 0 | E15: =IF(C15<D15,"Place Order","") | G15: Wiper (Large size) | H15: 0 | K15: Wiper (Large size) | L15: 0
A16: 0 | B16: Wiper for Washroom (Small size) | C16: =A16+H16-L16 -> 0 | D16: 0 | E16: =IF(C16<D16,"Place Order","") | G16: Wiper for Washroom (Small size) | H16: 0 | K16: Wiper for Washroom (Small size) | L16: 0
A17: =H17-L17 -> 0 | B17: Mop (Dry) | C17: =H17-L17 -> 0 | D17: 0 | E17: =IF(C17<D17,"Place Order","") | G17: Mop (Dry) | H17: 0 | K17: Mop (Dry) | L17: 0
A18: =H18-L18 -> 0 | B18: Mop (Wet) | C18: =H18-L18 -> 0 | D18: 0 | E18: =IF(C18<D18,"Place Order","") | G18: Mop (Wet) | H18: 0 | K18: Mop (Wet) | L18: 0
A19: 0 | B19: Surf (500 GRM) Pkt | C19: 1 | D19: 2 | E19: =IF(C19<D19,"Place Order","") -> Place Order | G19: Surf (500 GRM) Pkt | H19: 0 | K19: Surf (500 GRM) Pkt | L19: 2
A20: 0 | B20: Sweep Tiger Bottle | C20: =A20+H20-L20 -> 0 | D20: 2 | E20: =IF(C20<D20,"Place Order","") -> Place Order | G20: Sweep Tiger Bottle | H20: 2 | K20: Sweep Tiger Bottle | L20: 2
A21: 0 | B21: Glint (500 ML) | C21: =H21-L21 -> 0 | D21: 1 | E21: =IF(C21<D21,"Place Order","") -> Place Order | G21: Glint (500 ML) | H21: 1 | K21: Glint (500 ML) | L21: 1
A22: =H22-L22 -> 2 | B22: Air Freshener Bottle Pack | C22: 2 | D22: 2 | E22: =IF(C22<D22,"Place Order","") | G22: Air Freshener Bottle Pack | H22: 2 | K22: Air Freshener Bottle Pack | L22: 0
A23: 0 | B23: Air Freshner (Air Wick) | C23: =A23+H23-L23 -> 0 | D23: 0 | E23: =IF(C23<D23,"Place Order","") | G23: Air Freshner (Air Wick) | H23: 0 | K23: Air Freshner (Air Wick) | L23: 0
A24: 0 | B24: Mortien Spray | C24: 2 | D24: 2 | E24: =IF(C24<D24,"Place Order","") | G24: Mortien Spray | H24: 0 | K24: Mortien Spray | L24: 1
A25: =H25-L25 -> 0 | B25: Disposable Glass | C25: =H25-L25 -> 0 | D25: 0 | E25: =IF(C25<D25,"Place Order","") | G25: Disposable Glass | H25: 0 | K25: Disposable Glass | L25: 0
A26: 0 | B26: Tissue Box Rose Petal Box | C26: =H26-L26 -> 0 | D26: 2 | E26: =IF(C26<D26,"Place Order","") -> Place Order | G26: Tissue Box Rose Petal Box | H26: 5 | K26: Tissue Box Rose Petal Box | L26: 5
A27: =H27-L27 -> 0 | B27: Toilet Roll Tissues Roll Pack | C27: =H27-L27 -> 0 | D27: 0 | E27: =IF(C27<D27,"Place Order","") | G27: Toilet Roll Tissues Roll Pack | H27: 0 | K27: Toilet Roll Tissues Roll Pack | L27: 0
A28: =H28-L28 -> 0 | B28: Towel (Medium) | C28: =H28-L28 -> 0 | D28: 0 | E28: =IF(C28<D28,"Place Order","") | G28: Towel (Medium) | H28: 0 | K28: Towel (Medium) | L28: 0
A29: =H29-L29 -> 0 | B29: Dust Bin | C29: =H29-L29 -> 0 | D29: 0 | E29: =IF(C29<D29,"Place Order","") | G29: Dust Bin | H29: 0 | K29: Dust Bin | L29: 0
A30: =H30-L30 -> 1 | B30: Dust Bin Bags (5 kg size) | C30: =H30-L30 -> 1 | D30: 2 | E30: =IF(C30<D30,"Place Order","") -> Place Order | G30: Dust Bin Bags (5 kg size) | H30: 2 | K30: Dust Bin Bags (5 kg size) | L30: 1
A31: =H31-L31 -> 1 | B31: Garbage Bags (20 Kg size) | C31: =H31-L31 -> 1 | D31: 2 | E31: =IF(C31<D31,"Place Order","") -> Place Order | G31: Garbage Bags (20 Kg size) | H31: 2 | K31: Garbage Bags (20 Kg size) | L31: 1
A32: 0 | B32: Dust Pan | C32: =H32-L32 -> 0 | D32: 0 | E32: =IF(C32<D32,"Place Order","") | G32: Dust Pan | H32: 0 | K32: Dust Pan | L32: 0
A33: =H33-L33 -> 0 | B33: Toilet Brush | C33: =H33-L33 -> 0 | D33: 0 | E33: =IF(C33<D33,"Place Order","") | G33: Toilet Brush | H33: 0 | K33: Toilet Brush | L33: 0
A34: =H34-L34 -> 0 | B34: Toilet Plunger | C34: =H34-L34 -> 0 | D34: 0 | E34: =IF(C34<D34,"Place Order","") | G34: Toilet Plunger | H34: 0 | K34: Toilet Plunger | L34: 0
B39: ________________________ | G39: ________________________ | K39: ________________________
B40: Prepared By | G40: Checked By | K40: Reviewed By
B41: Atiqa Saeed | G41: Muhammad Saadat | K41: Zeeshan Nasar
B42: Admin Cum Program | G42: Sr. Admin Officer | K42: Operations Manager

Sheet Stationery Items Stock Sheet 
A1: AHKF Monthly Stationery Stock Report Dhouk Hassu
A2: Month of April 2026
A3: Opening Stock | B3: Balance Stock | D3: Minimum Stock to be Kept | E3: Procurement Sugestions | F3: Stock IN | J3: Stock OUT
B4: Product Name | C4: Quantity | F4: Date | G4: Product Name | H4: Quantity | I4: Status | J4: Date | K4: Product Name | L4: Quantity | M4: Status
A5: 0 | B5: AHKF Card Folder A/4 | C5: =A5+H5-L5 -> 0 | E5: =IF(C5<D5,"Place Order","") | G5: AHKF Card Folder A/4 | H5: 0 | K5: AHKF Card Folder A/4 | L5: 0
A6: 0 | B6: AHKF Envelopes A/4 | C6: =A6+H6-L6 -> 0 | E6: =IF(C6<D6,"Place Order","") | G6: AHKF Envelopes A/4 | H6: 0 | K6: AHKF Envelopes A/4 | L6: 0
A7: 0 | B7: AHKF Envelopes F/5 | C7: =A7+H7-L7 -> 0 | E7: =IF(C7<D7,"Place Order","") | G7: AHKF Envelopes F/5 | H7: 0 | K7: AHKF Envelopes F/5 | L7: 0
A8: 0 | B8: AHKF Envelopes L/S | C8: =A8+H8-L8 -> 0 | E8: =IF(C8<D8,"Place Order","") | G8: AHKF Envelopes L/S | H8: 0 | K8: AHKF Envelopes L/S | L8: 0
A9: 0 | B9: AHKRC Card Folder A/4 | C9: 0 | E9: =IF(C9<D9,"Place Order","") | G9: AHKRC Card Folder A/4 | H9: 0 | K9: AHKRC Card Folder A/4 | L9: 0
A10: 0 | B10: AHKRC Envelopes A/4 | C10: =A10+H10-L10 -> 50 | E10: =IF(C10<D10,"Place Order","") | G10: AHKRC Envelopes A/4 | H10: 50 | K10: AHKRC Envelopes A/4 | L10: 0
A11: 0 | B11: AHKRC Envelopes F/5 | C11: =A11+H11-L11 -> 0 | E11: =IF(C11<D11,"Place Order","") | G11: AHKRC Envelopes F/5 | H11: 0 | K11: AHKRC Envelopes F/5 | L11: 0
A12: 0 | B12: AHKRC Envelopes L/S | C12: =A12+H12-L12 -> 0 | E12: =IF(C12<D12,"Place Order","") | G12: AHKRC Envelopes L/S | H12: 0 | K12: AHKRC Envelopes L/S | L12: 0
A13: 0 | B13: Arrow Flags | C13: =A13+H13-L13 -> 0 | E13: =IF(C13<D13,"Place Order","") | G13: Arrow Flags | H13: 0 | K13: Arrow Flags | L13: 0
A14: 10 | B14: Ball Point | C14: =A14+H14-L14 -> 6 | D14: 10 | E14: =IF(C14<D14,"Place Order","") -> Place Order | G14: Ball Point | H14: 0 | K14: Ball Point | L14: 4
A15: 0 | B15: Binder clips (Large) | C15: =A15+H15-L15 -> 0 | E15: =IF(C15<D15,"Place Order","") | G15: Binder clips (Large) | H15: 0 | K15: Binder clips (Large) | L15: 0
A16: 0 | B16: Binder clips (Medium) | C16: =A16+H16-L16 -> 0 | E16: =IF(C16<D16,"Place Order","") | G16: Binder clips (Medium) | H16: 0 | K16: Binder clips (Medium) | L16: 0
A17: 0 | B17: Binder clips (Small) | C17: =A17+H17-L17 -> 0 | E17: =IF(C17<D17,"Place Order","") | G17: Binder clips (Small) | H17: 0 | K17: Binder clips (Small) | L17: 0
A18: 2 | B18: Binding Tape (2") | C18: =A18+H18-L18 -> 2 | E18: =IF(C18<D18,"Place Order","") | G18: Binding Tape (2") | H18: 0 | K18: Binding Tape (2") | L18: 0
A19: 0 | B19: Board Eraser | C19: =A19+H19-L19 -> 0 | E19: =IF(C19<D19,"Place Order","") | G19: Board Eraser | H19: 0 | K19: Board Eraser | L19: 0
A20: 8 | B20: Board Marker | C20: =A20+H20-L20 -> 0 | E20: =IF(C20<D20,"Place Order","") | G20: Board Marker | H20: 0 | K20: Board Marker | L20: 8
A21: 0 | B21: Board Push Pin | C21: =A21+H21-L21 -> 0 | E21: =IF(C21<D21,"Place Order","") | G21: Board Push Pin | H21: 0 | K21: Board Push Pin | L21: 0
A22: 4 | B22: Box File | C22: =A22-L22 -> 2 | E22: =IF(C22<D22,"Place Order","") | G22: Box File | H22: 4 | K22: Box File | L22: 2
A23: 0 | B23: Calculator (Casio)(Medium) | C23: =A23+H23-L23 -> 0 | E23: =IF(C23<D23,"Place Order","") | G23: Calculator (Casio)(Medium) | H23: 0 | K23: Calculator (Casio)(Medium) | L23: 0
A24: 0 | B24: Color Page (A/4) Pkt | C24: =A24+H24-L24 -> 0 | E24: =IF(C24<D24,"Place Order","") | G24: Color Page (A/4) Pkt | H24: 0 | K24: Color Page (A/4) Pkt | L24: 0
A25: 0 | B25: Double Tape | C25: =H25-L25 -> 1 | E25: =IF(C25<D25,"Place Order","") | G25: Double Tape | H25: 1 | K25: Double Tape | L25: 0
A26: 5 | B26: Eraser | C26: =A26+H26-L26 -> 5 | D26: 2 | E26: =IF(C26<D26,"Place Order","") | G26: Eraser | H26: 0 | K26: Eraser | L26: 0
A27: 0 | B27: File Folder (Button Plastic) | C27: =A27+H27-L27 -> 0 | E27: =IF(C27<D27,"Place Order","") | G27: File Folder (Button Plastic) | H27: 0 | K27: File Folder (Button Plastic) | L27: 0
A28: 3 | B28: Highlighter Pen | C28: =A28-L28 -> 3 | D28: 1 | E28: =IF(C28<D28,"Place Order","") | G28: Highlighter Pen | H28: 0 | K28: Highlighter Pen | L28: 0
A29: 0 | B29: Ink Pot | C29: =A29+H29-L29 -> 0 | E29: =IF(C29<D29,"Place Order","") | G29: Ink Pot | H29: 0 | K29: Ink Pot | L29: 0
A30: 0 | B30: Inkpad | C30: =A30+H30-L30 -> 0 | E30: =IF(C30<D30,"Place Order","") | G30: Inkpad | H30: 0 | K30: Inkpad | L30: 0
A31: 5 | B31: Led Pencil | C31: =A31+H31-L31 -> 5 | D31: 2 | E31: =IF(C31<D31,"Place Order","") | G31: Led Pencil | H31: 0 | K31: Led Pencil | L31: 0
A32: 0 | B32: Letter Dispatched Register | C32: =A32+H32-L32 -> 0 | E32: =IF(C32<D32,"Place Order","") | G32: Letter Dispatched Register | H32: 0 | K32: Letter Dispatched Register | L32: 0
A33: 0 | B33: Letter Receiving Register | C33: =A33+H33-L33 -> 0 | E33: =IF(C33<D33,"Place Order","") | G33: Letter Receiving Register | H33: 0 | K33: Letter Receiving Register | L33: 0
A34: 0 | B34: Masking Paper Tape (1") | C34: =A34+H34-L34 -> 0 | E34: =IF(C34<D34,"Place Order","") | G34: Masking Paper Tape (1") | H34: 0 | K34: Masking Paper Tape (1") | L34: 0
A35: 0 | B35: Masking Paper Tape (2") | C35: =A35+H35-L35 -> 0 | E35: =IF(C35<D35,"Place Order","") | G35: Masking Paper Tape (2") | H35: 0 | K35: Masking Paper Tape (2") | L35: 0
A36: 0 | B36: Masking Paper Tape (5") | C36: =A36+H36-L36 -> 0 | E36: =IF(C36<D36,"Place Order","") | G36: Masking Paper Tape (5") | H36: 0 | K36: Masking Paper Tape (5") | L36: 0
A37: 0 | B37: Masking Paper Tape (7") | C37: =A37+H37-L37 -> 0 | E37: =IF(C37<D37,"Place Order","") | G37: Masking Paper Tape (7") | H37: 0 | K37: Masking Paper Tape (7") | L37: 0
A38: 0 | B38: Paper clip (30 mm) | C38: =A38+H38-L38 -> 0 | E38: =IF(C38<D38,"Place Order","") | G38: Paper clip (30 mm) | H38: 0 | K38: Paper clip (30 mm) | L38: 0
A39: 0 | B39: Paper cutter | C39: =A39+H39-L39 -> 0 | E39: =IF(C39<D39,"Place Order","") | G39: Paper cutter | H39: 0 | K39: Paper cutter | L39: 0
A40: 3 | B40: Paper Rim A/4 (AA) 80 Grm | C40: =A40+H40-L40 -> 1 | D40: 2 | E40: =IF(C40<D40,"Place Order","") -> Place Order | G40: Paper Rim A/4 (AA) 80 Grm | H40: 0 | K40: Paper Rim A/4 (AA) 80 Grm | L40: 2
...

Sheet Monthly Cost Breakup
A1: AHKF Monthly Stationery Stock Report Dhouk Hassu
A2: March 2026
A3: Groceries M/O March 2026 | F3: Janitorial M/O March 2026 | K3: Stationery M/O March 26
A4: Product Name | B4: Quantity | C4: Unit Price | D4: Total Cost | F4: Product Name | G4: Quantity | H4: Unit Price | I4: Total Cost | K4: Product Name | L4: Quantity | M4: Unit Price | N4: Total Cost
A5: Everyday Milk Powder(850 Grams) | B5: =+'DH Grocery Items'!L5 -> 2 | C5: 1603.1 | D5: =C5*B5 -> 3206.2 | F5: Phynenyl (2.75 Lit) | G5: =+'DH Janitorial Items'!L5 -> 1 | H5: 450.13 | I5: =H5*G5 -> 450.13 | K5: AHKF Card Folder A/4 | L5: =+'Stationery Items Stock Sheet '!L5 -> 0 | M5: 90 | N5: =M5*L5 -> 0
A6: White Sugar Kg | B6: =+'DH Grocery Items'!L6 -> 1 | C6: 140.35 | D6: =C6*B6 -> 140.35 | F6: Broom-Phool Jharoo | G6: =+'DH Janitorial Items'!L6 -> 1 | H6: 199.5 | I6: =H6*G6 -> 199.5 | K6: AHKF Envelopes A/4 | L6: =+'Stationery Items Stock Sheet '!L6 -> 0 | M6: 20 | N6: =M6*L6 -> 0
A7: Tea (Open)(500 Grams) Pkt | B7: =+'DH Grocery Items'!L7 -> 1 | C7: 1171.93 | D7: =C7*B7 -> 1171.93 | F7: Broom-Jharoo (Bamboo) | G7: =+'DH Janitorial Items'!L7 -> 0 | H7: 199.5 | I7: =H7*G7 -> 0 | K7: AHKF Envelopes F/5 | L7: =+'Stationery Items Stock Sheet '!L7 -> 0 | M7: 50 | N7: =M7*L7 -> 0
A8: Tea Black (100 Bags) Pkt | B8: =+'DH Grocery Items'!L8 -> 0 | C8: 1151.88 | D8: =C8*B8 -> 0 | F8: Brush Cleaning with Rode (Jala) | G8: =+'DH Janitorial Items'!L8 -> 0 | H8: 440.1 | I8: =H8*G8 -> 0 | K8: AHKF Envelopes L/S | L8: =+'Stationery Items Stock Sheet '!L8 -> 0 | M8: 12 | N8: =M8*L8 -> 0
A9: Green Tea (25 Bags) Pkt | B9: =+'DH Grocery Items'!L8 -> 0 | C9: 239.6 | D9: =C9*B9 -> 0 | F9: Duster Cloth | G9: =+'DH Janitorial Items'!L9 -> 1 | H9: 89.22 | I9: =H9*G9 -> 89.22 | K9: AHKRC Card Folder A/4 | L9: =+'Stationery Items Stock Sheet '!L9 -> 0 | M9: 20 | N9: =M9*L9 -> 0
A10: Coffee (Nescafe 200 gm) Jar | B10: =+'DH Grocery Items'!L9 -> 0 | C10: 239.6 | D10: =C10*B10 -> 0 | F10: Harpic (750 ml) bottle | G10: =+'DH Janitorial Items'!L10 -> 1 | H10: 816.04 | I10: =H10*G10 -> 816.04 | K10: AHKRC Envelopes A/4 | L10: =+'Stationery Items Stock Sheet '!L10 -> 0 | M10: 20 | N10: =M10*L10 -> 0
A11: Biscuit (Half Rolls) | B11: =+'DH Grocery Items'!L10 -> 0 | C11: 40.1 | D11: =C11*B11 -> 0 | F11: Hand Washing Soap (Large size) | G11: =+'DH Janitorial Items'!L11 -> 1 | H11: 128.32 | I11: =H11*G11 -> 128.32 | K11: AHKRC Envelopes F/5 | L11: =+'Stationery Items Stock Sheet '!L11 -> 0 | M11: 30 | N11: =M11*L11 -> 0
A12: Grand total | D12: =SUM(D5:D11) -> 4518.48 | F12: Hand Wash Liquid (1 Liter) | G12: =+'DH Janitorial Items'!L12 -> 0 | H12: 971.43 | I12: =H12*G12 -> 0 | K12: AHKRC Envelopes L/S | L12: =+'Stationery Items Stock Sheet '!L12 -> 0 | M12: 12 | N12: =M12*L12 -> 0
F13: Scotch Brite | G13: =+'DH Janitorial Items'!L13 -> 0 | H13: 159.4 | I13: =H13*G13 -> 0 | K13: Arrow Flags | L13: =+'Stationery Items Stock Sheet '!L13 -> 0 | M13: 90 | N13: =M13*L13 -> 0
F14: Lemon Max (275 ML) | G14: =+'DH Janitorial Items'!L14 -> 1 | H14: 359.9 | I14: =H14*G14 -> 359.9 | K14: Ball Point | L14: =+'Stationery Items Stock Sheet '!L14 -> 4 | M14: 15 | N14: =M14*L14 -> 60
F15: Wiper for Washroom (Small size) | G15: =+'DH Janitorial Items'!L16 -> 0 | H15: 500 | I15: =H15*G15 -> 0 | K15: Binder clips (Large) | L15: =+'Stationery Items Stock Sheet '!L15 -> 0 | M15: 75 | N15: =M15*L15 -> 0
F16: Mop (Dry) | G16: =+'DH Janitorial Items'!L17 -> 0 | H16: 1151.88 | I16: =H16*G16 -> 0 | K16: Binder clips (Medium) | L16: =+'Stationery Items Stock Sheet '!L16 -> 0 | M16: 45 | N16: =M16*L16 -> 0
F17: Mop (Wet) | G17: =+'DH Janitorial Items'!L18 -> 0 | H17: 891.23 | I17: =H17*G17 -> 0 | K17: Binder clips (Small) | L17: =+'Stationery Items Stock Sheet '!L17 -> 0 | M17: 20 | N17: =M17*L17 -> 0
F18: Surf (500 GRM) Pkt | G18: =+'DH Janitorial Items'!L19 -> 2 | H18: 269.67 | I18: =H18*G18 -> 539.34 | K18: Binding Tape (2") | L18: =+'Stationery Items Stock Sheet '!L18 -> 0 | M18: 160 | N18: =M18*L18 -> 0
F19: Sweep Tiger Bottle | G19: =+'DH Janitorial Items'!L20 -> 2 | H19: 54.14 | I19: =H19*G19 -> 108.28 | K19: Board Eraser | L19: =+'Stationery Items Stock Sheet '!L19 -> 0 | M19: 80 | N19: =M19*L19 -> 0
F20: Glint (500 ML) | G20: =+'DH Janitorial Items'!L21 -> 1 | H20: 650.63 | I20: =H20*G20 -> 650.63 | K20: Board Marker | L20: =+'Stationery Items Stock Sheet '!L20 -> 8 | M20: 50 | N20: =M20*L20 -> 400
F21: Air Freshener Bottle Pack | G21: =+'DH Janitorial Items'!L22 -> 0 | H21: 310 | I21: =H21*G21 -> 0 | K21: Board Push Pin | L21: =+'Stationery Items Stock Sheet '!L21 -> 0 | M21: 80 | N21: =M21*L21 -> 0
I22: =H22*G22 -> 0 | K22: Box File (Blue color) | L22: =+'Stationery Items Stock Sheet '!L22 -> 2 | M22: 350 | N22: =M22*L22 -> 700
F23: Mortien Spray | G23: =+'DH Janitorial Items'!L24 -> 1 | H23: 831.08 | I23: =H23*G23 -> 831.08 | K23: Calculator (Casio)(Medium) | L23: =+'Stationery Items Stock Sheet '!L23 -> 0 | M23: 1000 | N23: =M23*L23 -> 0
F24: Toilet Roll Tissues Roll Pack | G24: =+'DH Janitorial Items'!L27 -> 0 | H24: 109.27 | I24: =H24*G24 -> 0 | K24: Color Page (A/4) Pkt | L24: =+'Stationery Items Stock Sheet '!L24 -> 0 | M24: 440 | N24: =M24*L24 -> 0
F25: Towel (Medium) | G25: =+'DH Janitorial Items'!L28 -> 0 | H25: 801 | I25: =H25*G25 -> 0 | K25: Double Tape | L25: =+'Stationery Items Stock Sheet '!L25 -> 0 | M25: 300 | N25: =M25*L25 -> 0
F26: Toilet Brush | G26: =+'DH Janitorial Items'!L33 -> 0 | H26: 259.65 | I26: =H26*G26 -> 0 | K26: Eraser | L26: =+'Stationery Items Stock Sheet '!L26 -> 0 | M26: 15 | N26: =M26*L26 -> 0
F27: Toilet Plunger | G27: =+'DH Janitorial Items'!L34 -> 0 | H27: 460.15 | I27: =H27*G27 -> 0 | K27: File Folder (Button Plastic) | L27: =+'Stationery Items Stock Sheet '!L27 -> 0 | M27: 20 | N27: =M27*L27 -> 0
F28: Grand Total | I28: =SUM(I5:I27) -> 4172.44 | K28: Folders Printer (AHKF) | L28: =+'Stationery Items Stock Sheet '!L28 -> 0 | M28: 90 | N28: =M28*L28 -> 0
K29: Folders Printer (AHKRC) | L29: =+'Stationery Items Stock Sheet '!L29 -> 0 | M29: 90 | N29: =M29*L29 -> 0
K30: Highlighter Pen | L30: =+'Stationery Items Stock Sheet '!L31 -> 0 | M30: 150 | N30: =M30*L30 -> 0
K31: Ink Pot | L31: =+'Stationery Items Stock Sheet '!L32 -> 0 | M31: 50 | N31: =M31*L31 -> 0
K32: Inkpad | L32: =+'Stationery Items Stock Sheet '!L33 -> 0 | M32: 50 | N32: =M32*L32 -> 0
K33: Led Pencil | L33: =+'Stationery Items Stock Sheet '!L34 -> 0 | M33: 18 | N33: =M33*L33 -> 0
K34: Letter Dispatched Register | L34: =+'Stationery Items Stock Sheet '!L34 -> 0 | M34: 480 | N34: =M34*L34 -> 0
K35: Letter Receiving Register | L35: =+'Stationery Items Stock Sheet '!L35 -> 0 | M35: 480 | N35: =M35*L35 -> 0
K36: Masking Paper Tape (1") | L36: =+'Stationery Items Stock Sheet '!L37 -> 0 | M36: 75 | N36: =M36*L36 -> 0
K37: Masking Paper Tape (2") | L37: =+'Stationery Items Stock Sheet '!L38 -> 0 | M37: 150 | N37: =M37*L37 -> 0
K38: Masking Paper Tape (5") | L38: =+'Stationery Items Stock Sheet '!L38 -> 0 | M38: 250 | N38: =M38*L38 -> 0
K39: Masking Paper Tape (7") | L39: =+'Stationery Items Stock Sheet '!L39 -> 0 | M39: 350 | N39: =M39*L39 -> 0
K40: Note pad (RADS Printed) | L40: =+'Stationery Items Stock Sheet '!L40 -> 2 | M40: 300 | N40: =M40*L40 -> 600
...
