Workbook

Sheet Grocery Items
A1: RADS Monthly Groceries Stock Report Head Office
A2: Month of April 2026
A3: Opening Stock 1st April,2026 | B3: Balance Stock | D3: Minimum Stock to be Kept | E3: Procurement Suggestion | F3: Stock In 22nd April,2026 | J3: Stock OUT (During the Month)
B4: Product Name | C4: Balance Quantity 30thApril,2026 | G4: Product Name | H4: Quantity | I4: Status | K4: Product Name | L4: Quantity | M4: Status
A5: 27 | B5: Everyday Milk Powder(850 Grams) | C5: 34 | D5: 10 | E5: =IF(C5<D5,"Place Order","") | G5: Everyday Milk Powder(850 Grams) | H5: 20 | K5: Everyday Milk Powder(850 Grams) | L5: 13
A6: 0 | B6: White Sugar Kg | C6: 0 | D6: 3 | E6: =IF(C6<D6,"Place Order","") -> Place Order | G6: White Sugar Kg | H6: 7 | K6: White Sugar Kg | L6: 7
A7: 24 | B7: Tea Black Pkt(100 bags) | C7: 28 | D7: 3 | E7: =IF(C7<D7,"Place Order","") | G7: Tea Black Pkt(100 bags) | H7: 15 | K7: Tea Black (100 Bags) Pkt | L7: 11
A8: 4 | B8: Green Tea (30 Bags) Pkt | C8: 7 | D8: 3 | E8: =IF(C8<D8,"Place Order","") | G8: Green Tea (30 Bags) Pkt | H8: 5 | K8: Green Tea (30 Bags) Pkt | L8: 2
A9: 0 | B9: Coffee (Nescafe 200 gm) Jar | C9: 1 | D9: 1 | E9: =IF(C9<D9,"Place Order","") | G9: Coffee (Nescafe 200 gm) Jar | H9: 2 | K9: Coffee (Nescafe 200 gm) Jar | L9: 1
A10: 28 | B10: Biscuit (Half Rolls) | C10: 35 | D10: 10 | E10: =IF(C10<D10,"Place Order","") | G10: Biscuit (Half Rolls) | H10: 14 | K10: Biscuit (Half Rolls) | L10: 0
B14: ________________________ | D14: ________________________ | G14: ________________________ | K14: ________________________
B15: Prepared By | D15: Reviewed By | G15: Checked By | K15: Approved By
B16: Raja Muneeb Islam | D16: Muhammad Saadat | G16: Muhammad Hasan | K16: Zeeshan Nasar
B17: Admin & Inventory Assistant | D17: Sr. Admin Officer | G17: Finance Officer | K17: Operations Manager

Sheet Janitorial Items
C1: RADS Monthly Janitorial Items Stock Report
C2: Month of April 2026
C3: Opening Stock 1st April, 26 | D3: Balance Stock | F3: Minimum Stock to be Kept | G3: Procurement Suggestion | H3: Stock In 22nd April, 2026 | L3: Stock OUT (During Month)
D4: Product Name | E4: Balance Quantity 30th April,26 | I4: Product Name | J4: Quantity | K4: Status | M4: Product Name | N4: Quantity | O4: Status
C5: 0 | D5: Phynenyl (2.75 Lit) | E5: 0 | F5: 2 | G5: =IF(E5<F5,"Place Order","") -> Place Order | I5: Phynenyl (2.75 Lit) | J5: 1 | M5: Phynenyl (2.75 Lit) | N5: 0
C6: =J6-N6 -> 0 | D6: Broom-Phool Jharoo | E6: =C6 -> 0 | F6: 1 | G6: =IF(E6<F6,"Place Order","") -> Place Order | I6: Broom-Phool Jharoo | J6: 2 | M6: Broom-Phool Jharoo | N6: 2
C7: 6 | D7: Broom-Jharoo (Bamboo) | E7: =C7+J7-N7 -> 6 | F7: 1 | G7: =IF(E7<F7,"Place Order","") | I7: Broom-Jharoo (Bamboo) | J7: 0 | M7: Broom-Jharoo (Bamboo) | N7: 0
C8: 1 | D8: Brush Cleaning with Rode (Jala) | E8: 1 | F8: 1 | G8: =IF(E8<F8,"Place Order","") | I8: Brush Cleaning with Rode (Jala) | J8: 0 | M8: Brush Cleaning with Rode (Jala) | N8: 0
C9: 0 | D9: Duster Cloth | E9: 0 | F9: 3 | G9: =IF(E9<F9,"Place Order","") -> Place Order | I9: Duster Cloth | J9: 2 | M9: Duster Cloth | N9: 2
C10: 5 | D10: Harpic (450ml) bottle | E10: 6 | F10: 2 | G10: =IF(E10<F10,"Place Order","") | I10: Harpic (450ml) bottle | J10: 3 | M10: Harpic (450ml) bottle | N10: 2
C11: 5 | D11: Dettol Hand Wash Bottle 250ml | E11: 7 | F11: 0 | G11: =+'Janitorial Items'!N10 -> 2 | I11: Dettol Hand Wash Bottle 250ml | J11: 6 | M11: Dettol Hand Wash Bottle 250ml | N11: 4
C12: =J12-N12 -> 0 | D12: Hand Washing Soap (Large size) | E12: =C12 -> 0 | F12: 0 | G12: =IF(E12<F12,"Place Order","") | I12: Hand Washing Soap (Large size) | J12: 0 | M12: Hand Washing Soap (Large size) | N12: 0
C13: =J13-N13 -> 0 | D13: Hand Wash Liquid (750 ML) | E13: =C13 -> 0 | F13: 1 | G13: =IF(E13<F13,"Place Order","") -> Place Order | I13: Hand Wash Liquid (750 ML) | J13: 0 | M13: Hand Wash Liquid (1 Liter) | N13: 0
C14: 4 | D14: Brite Sun Spunch | E14: 4 | F14: 4 | G14: =IF(E14<F14,"Place Order","") | I14: Sun Brite | J14: 3 | M14: Sun Brite | N14: 3
C15: 8 | D15: Lemon Max (475 ML) | E15: 8 | F15: 1 | G15: =IF(E15<F15,"Place Order","") | I15: Lemon Max (475 ML) | J15: 3 | M15: Lemon Max (475 ML) | N15: 3
C16: 4 | D16: Wiper (Large size) | E16: =C16 -> 4 | F16: 1 | G16: =IF(E16<F16,"Place Order","") | I16: Wiper (Large size) | J16: 0 | M16: Wiper (Large size) | N16: 0
C17: 3 | D17: Wiper for Washroom (Small size) | E17: 3 | F17: 1 | G17: =IF(E17<F17,"Place Order","") | I17: Wiper for Washroom (Small size) | J17: 0 | M17: Wiper for Washroom (Small size) | N17: 0
C18: 1 | D18: Mop (Dry) | E18: =C18 -> 1 | F18: 1 | G18: =IF(E18<F18,"Place Order","") | I18: Mop (Dry) | J18: 0 | M18: Mop (Dry) | N18: 0
C19: 1 | D19: Mop (Wet) | E19: 1 | F19: 1 | G19: =IF(E19<F19,"Place Order","") | I19: Mop (Wet) | J19: 2 | M19: Mop (Wet) | N19: 2
C20: 3 | D20: Surf (500 GRM) Pkt | E20: 5 | F20: 3 | G20: =IF(E20<F20,"Place Order","") | I20: Surf (500 GRM) Pkt | J20: 4 | M20: Surf (500 GRM) Pkt | N20: 2
C21: 0 | D21: Sweep Tiger Bottle | E21: 0 | F21: 2 | G21: =IF(E21<F21,"Place Order","") -> Place Order | I21: Sweep Tiger Bottle | J21: 0 | M21: Sweep Tiger Bottle | N21: 0
C22: 0 | D22: Glint (500 ML) | E22: 0 | F22: 1 | G22: =IF(E22<F22,"Place Order","") -> Place Order | I22: Glint (500 ML) | J22: 1 | M22: Glint (500 ML) | N22: 1
C23: =J23-N23 -> 0 | D23: Air Freshener Bottle Pack | E23: =C23 -> 0 | F23: 2 | G23: =IF(E23<F23,"Place Order","") -> Place Order | I23: Air Freshener Bottle Pack | J23: 2 | M23: Air Freshener Bottle Pack | N23: 2
C24: 14 | D24: Air Freshner (Air Wick) | E24: 13 | F24: 4 | G24: =IF(E24<F24,"Place Order","") | I24: Air Freshner (Air Wick) | J24: 0 | M24: Air Freshner (Air Wick) | N24: 1
C25: 0 | D25: Mortien Spray | E25: 0 | F25: 2 | G25: =IF(E25<F25,"Place Order","") -> Place Order | I25: Mortien Spray | J25: 0 | M25: Mortien Spray | N25: 0
C26: =J26-N26 -> 0 | D26: Disposable Glass | E26: =C26 -> 0 | F26: 150 | G26: =IF(E26<F26,"Place Order","") -> Place Order | I26: Disposable Glass | J26: 0 | M26: Disposable Glass | N26: 0
C27: 5 | D27: Tissue Box Rose Petal Box | E27: 7 | F27: 10 | G27: =IF(E27<F27,"Place Order","") -> Place Order | I27: Tissue Box Rose Petal Box | J27: 10 | M27: Tissue Box Rose Petal Box | N27: 8
C28: 114 | D28: Toilet Roll Tissues Roll Pack | E28: 154 | F28: 100 | G28: =IF(E28<F28,"Place Order","") | I28: Toilet Roll Tissues Roll Pack | J28: 150 | M28: Toilet Roll Tissues Roll Pack | N28: 110
C29: =J29-N29 -> 0 | D29: Towel (Medium) | E29: =C29 -> 0 | F29: 1 | G29: =IF(E29<F29,"Place Order","") -> Place Order | I29: Towel (Medium) | J29: 0 | M29: Towel (Medium) | N29: 0
C30: 0 | D30: Dust Bin | E30: 0 | F30: 1 | G30: =IF(E30<F30,"Place Order","") -> Place Order | I30: Dust Bin | J30: 0 | M30: Dust Bin | N30: 0
C31: 1 | D31: Garbage Bag (size 20" x 24") | E31: 3 | F31: 2 | G31: =IF(E31<F31,"Place Order","") | I31: Dust Bin Bags (size 20" x 24") | J31: 4 | M31: Dust Bin Bags (size 20" x 24") | N31: 2
C32: 6 | D32: Garbage Bags (20" x 30") | E32: 7 | F32: 1 | G32: =IF(E32<F32,"Place Order","") | I32: Garbage Bags (20" x 30") | J32: 5 | M32: Garbage Bags (20" x 30") | N32: 4
C33: 3 | D33: Garbage Bags (22" x 32") | E33: 5 | I33: Garbage Bags (22" x 32") | J33: 5 | M33: Garbage Bags (22" x 32") | N33: 3
C34: =J34-N34 -> 0 | D34: Dust Pan | E34: 0 | F34: 1 | G34: =IF(E34<F34,"Place Order","") -> Place Order | I34: Dust Pan | J34: 0 | M34: Dust Pan | N34: 0
C35: 0 | D35: Toilet Brush | E35: 0 | F35: 3 | G35: =IF(E35<F35,"Place Order","") -> Place Order | I35: Toilet Brush | J35: 1 | M35: Toilet Brush | N35: 1
C36: 1 | D36: Dettol Surface Cleaner 1Ltr | E36: 1 | F36: 1 | G36: =IF(E36<F36,"Place Order","") | I36: Dettol Surface Cleaner 1Ltr | J36: 0 | M36: Dettol Surface Cleaner 1Ltr | N36: 0
C37: 1 | D37: Anti Dust Broom (Brush)Cleaner | E37: 1 | F37: 1 | I37: Anti Dust Broom (Brush)Cleaner | J37: 2 | M37: Anti Dust Broom (Brush)Cleaner | N37: 2
C38: 0 | D38: Window Cleaning Brush | E38: 0 | F38: 1 | I38: Window cleaning brush | J38: 1 | M38: Multi Purpose Cleaner( window cleaning brush) | N38: 1
C39: 2 | D39: Toilet Plunger | E39: 2 | F39: 2 | G39: =IF(E39<F39,"Place Order","") | I39: Toilet Plunger | J39: 0 | M39: Toilet Plunger | N39: 0
D45: ________________________ | F45: ________________________ | I45: ________________________ | M45: ________________________
...

Sheet Stationery Items Stock Sheet 
A1: RADS Monthly Stationery Stock Report
A2: RADS Monthly Stationary Items Stock Report
A3: Month of April 2026
A4: Opening Stock 1st April,2026 | B4: Balance Stock | D4: Minimum Stock to be Kept | E4: Procurement Sugestions | F4: Stock IN 22nd April,2026 | J4: Stock Out (During Month)
B5: Product Name | C5: Balance Quantity 30th April,2026 | G5: Product Name | H5: Quantity | I5: Status | K5: Product Name | L5: Quantity | M5: Status
A6: 163 | B6: AHKF Card Folder A/4 | C6: 144 | D6: 25 | E6: =IF(C6<D6,"Place Order","") | G6: AHKF Card Folder A/4 | H6: 0 | K6: AHKF Card Folder A/4 | L6: 19
A7: 300 | B7: AHKF Envelopes A/4 | C7: 300 | D7: 25 | E7: =IF(C7<D7,"Place Order","") | G7: AHKF Envelopes A/4 | H7: 0 | K7: AHKF Envelopes A/4 | L7: 0
A8: 0 | B8: AHKF Envelopes A/5 | C8: =A8+H8-L8 -> 0 | D8: 25 | E8: =IF(C8<D8,"Place Order","") -> Place Order | G8: AHKF Envelopes A/5 | H8: 0 | K8: AHKF Envelopes A/5 | L8: 0
A9: 310 | B9: AHKF Envelopes L/S | C9: =A9+H9-L9 -> 310 | D9: 25 | E9: =IF(C9<D9,"Place Order","") | G9: AHKF Envelopes L/S | H9: 0 | K9: AHKF Envelopes L/S | L9: 0
A10: 0 | B10: AHKRC Card Folder A/4 | C10: =A10+H10-L10 -> 0 | D10: 25 | E10: =IF(C10<D10,"Place Order","") -> Place Order | G10: AHKRC Card Folder A/4 | H10: 0 | K10: AHKRC Card Folder A/4 | L10: 0
A11: 7 | B11: AHKF Diary (New) | C11: 6 | D11: 0 | E11: =IF(C11<D11,"Place Order","") | G11: AHKF Diary (New) | H11: 0 | K11: AHKF Diary (New) | L11: 1
A12: 351 | B12: AHKRC Envelopes A/4 | C12: 351 | D12: 25 | E12: =IF(C12<D12,"Place Order","") | G12: AHKRC Envelopes A/4 | H12: 0 | K12: AHKRC Envelopes A/4 | L12: 0
A13: 300 | B13: AHKRC Envelopes A/5 | C13: =A13+H13-L13 -> 300 | D13: 25 | E13: =IF(C13<D13,"Place Order","") | G13: AHKRC Envelopes A/5 | H13: 0 | K13: AHKRC Envelopes A/5 | L13: 0
A14: 0 | B14: AHKRC Envelopes L/S | C14: 0 | D14: 25 | E14: =IF(C14<D14,"Place Order","") -> Place Order | G14: AHKRC Envelopes L/S | H14: 0 | K14: AHKRC Envelopes L/S | L14: 0
A15: 6 | B15: Arrow Flags | C15: 6 | D15: 3 | E15: =IF(C15<D15,"Place Order","") | G15: Arrow Flags | H15: 0 | K15: Arrow Flags | L15: 0
A16: 0 | B16: Ball Point | C16: 0 | D16: 50 | E16: =IF(C16<D16,"Place Order","") -> Place Order | G16: Ball Point | H16: 0 | K16: Ball Point | L16: 0
A17: 40 | B17: Ball Point (Piano) | C17: 50 | D17: 0 | E17: =IF(C17<D17,"Place Order","") | G17: Ball Point (Piano) | H17: 20 | K17: Ball Point (Piano) | L17: 10
A18: 4 | B18: Binder clips (Large) Nos | C18: 0 | D18: 10 | E18: =IF(C18<D18,"Place Order","") -> Place Order | G18: Binder clips (Large) | H18: 0 | K18: Binder clips (Large) | L18: 4
A19: 14 | B19: Binder clips (Medium) Nos | C19: =A19+H19-L19 -> 14 | D19: 2 | E19: =IF(C19<D19,"Place Order","") | G19: Binder clips (Medium) | H19: 0 | K19: Binder clips (Medium) | L19: 0
A20: 20 | B20: Binder clips (Small) Nos | C20: 20 | D20: 10 | E20: =IF(C20<D20,"Place Order","") | G20: Binder clips (Small) | H20: 0 | K20: Binder clips (Small) | L20: 0
A21: 0 | B21: Binding Tape (2") | C21: 0 | D21: 3 | E21: =IF(C21<D21,"Place Order","") -> Place Order | G21: Binding Tape (2") | H21: 0 | K21: Binding Tape (2") | L21: 0
A22: 0 | B22: Board Eraser | C22: 0 | D22: 1 | E22: =IF(C22<D22,"Place Order","") -> Place Order | G22: Board Eraser | H22: 0 | K22: Board Eraser | L22: 0
A23: 111 | B23: Board Marker | C23: 111 | D23: 20 | E23: =IF(C23<D23,"Place Order","") | G23: Board Marker | H23: 0 | K23: Board Marker | L23: 0
A24: 8 | B24: Box File | C24: 15 | D24: 6 | E24: =IF(C24<D24,"Place Order","") | G24: Box File | H24: 10 | K24: Box File | L24: 3
A25: 1 | B25: Calculator (Casio)(Medium) | C25: =A25+H25-L25 -> 1 | D25: 0 | E25: =IF(C25<D25,"Place Order","") | G25: Calculator (Casio)(Medium) | H25: 0 | K25: Calculator (Casio)(Medium) | L25: 0
A26: 1 | B26: Calculator (Citizen) | C26: 1 | D26: 1 | E26: =IF(C26<D26,"Place Order","") | G26: Calculator (Citizen) | H26: 0 | K26: Calculator (Citizen) | L26: 1
A27: 3 | B27: Carbon Paper (Pkt) | C27: =A27+H27-L27 -> 3 | D27: 2 | E27: =IF(C27<D27,"Place Order","") | G27: Carbon Paper (Pkt) | H27: 0 | K27: Carbon Paper (Pkt) | L27: 0
A28: 8 | B28: Color Page (A/4) Pkt | C28: 8 | D28: 5 | E28: =IF(C28<D28,"Place Order","") | G28: Color Page (A/4) Pkt | H28: 0 | K28: Color Page (A/4) Pkt | L28: 0
A29: 1 | B29: Double Tape | C29: 2 | D29: 3 | E29: =IF(C29<D29,"Place Order","") -> Place Order | G29: Double Tape | H29: 2 | K29: Double Tape | L29: 1
A30: 0 | B30: Envelopes White (A/4) | C30: 29 | D30: 25 | E30: =IF(C30<D30,"Place Order","") | G30: Envelopes White (A/4) | H30: 29 | K30: Envelopes White (A/4) | L30: 0
A31: 30 | B31: Envelopes White (A/5) | C31: 30 | D31: 25 | E31: =IF(C31<D31,"Place Order","") | G31: Envelopes White (A/5) | H31: 0 | K31: Envelopes White (A/5) | L31: 0
A32: 30 | B32: Envelopes White (L/S) | C32: 200 | D32: 25 | E32: =IF(C32<D32,"Place Order","") | G32: Envelopes White (L/S) | H32: 170 | K32: Envelopes White (L/S) | L32: 0
A33: 62 | B33: Eraser | C33: 62 | D33: 10 | E33: =IF(C33<D33,"Place Order","") | G33: Eraser | H33: 0 | K33: Eraser | L33: 0
A34: 2 | B34: File Folder (Button Plastic) | C34: 2 | D34: 3 | E34: =IF(C34<D34,"Place Order","") -> Place Order | G34: File Folder (Button Plastic) | H34: 0 | K34: File Folder (Button Plastic) | L34: 0
A35: 34 | B35: Highlighter Pen | C35: 34 | D35: 2 | E35: =IF(C35<D35,"Place Order","") | G35: Highlighter Pen | H35: 0 | K35: Highlighter Pen | L35: 0
A36: 0 | B36: Ink Pot | C36: 0 | D36: 1 | E36: =IF(C36<D36,"Place Order","") -> Place Order | G36: Ink Pot | H36: 0 | K36: Ink Pot | L36: 0
A37: 3 | B37: Inkpad | C37: 3 | D37: 1 | E37: =IF(C37<D37,"Place Order","") | G37: Inkpad | H37: 0 | K37: Inkpad | L37: 0
A38: 12 | B38: Led Pencil | C38: 12 | D38: 10 | E38: =IF(C38<D38,"Place Order","") | G38: Led Pencil | H38: 0 | K38: Led Pencil | L38: 0
A39: 2 | B39: Letter Dispatched Register | C39: 2 | D39: 1 | E39: =IF(C39<D39,"Place Order","") | G39: Letter Dispatched Register | H39: 0 | K39: Letter Dispatched Register | L39: 0
... A45: 1 | B45: Packing Tape (2") | C45: 1 | D45: 1 | E45: =IF(C45<D45,"Place Order","") | G45: Packing Tape (2") | H45: 1 | K45: Packing Tape (2") | L45: 1
...

Sheet Monthly Cost Breakup
A1: RADS Monthly Breakup of Office Supplies (Head Office)
A2: April, 2026
A3: Groceries M/O April 2026 | F3: Janitorial M/O April,2026 | K3: Stationery M/O April,2026
A4: Product Name | B4: Quantity | C4: Unit Price | D4: Total Cost | F4: Product Name | G4: Quantity | H4: Unit Price | I4: Total Cost | K4: Product Name | L4: Quantity | M4: Unit Price | N4: Total Cost
A5: Everyday Milk Powder(850 Grams) | B5: =+'Grocery Items'!L5 -> 13 | C5: 1649 | D5: =C5*B5 -> 21437 | F5: Phynenyl (2.75 Lit) | G5: =+'Janitorial Items'!N5 -> 0 | H5: 481 | I5: =H5*G5 -> 0 | K5: AHKF Card Folder A/4 | L5: 0 | M5: 112 | N5: =M5*L5 -> 0
A6: White Sugar Kg | B6: =+'Grocery Items'!L6 -> 7 | C6: 151 | D6: =C6*B6 -> 1057 | F6: Broom-Phool Jharoo | G6: =+'Janitorial Items'!N6 -> 2 | H6: 300 | I6: =H6*G6 -> 600 | K6: AHKF Envelopes A/4 | L6: =+'Stationery Items Stock Sheet '!L7 -> 0 | M6: 20 | N6: =M6*L6 -> 0
A7: Tea Black (100 Bags) Pkt | B7: =+'Grocery Items'!L7 -> 11 | C7: 1152 | D7: =C7*B7 -> 12672 | F7: Brush Cleaning with Rode (Jala) | G7: =+'Janitorial Items'!N8 -> 0 | H7: 400 | I7: =H7*G7 -> 0 | K7: AHKF Envelopes L/S | L7: =+'Stationery Items Stock Sheet '!L9 -> 0 | M7: 12 | N7: =M7*L7 -> 0
A9: Green Tea (25 Bags) Pkt | B9: =+'Grocery Items'!L8 -> 2 | C9: 245 | D9: =C9*B9 -> 490 | F9: Duster Cloth | G9: =+'Janitorial Items'!N9 -> 2 | H9: 400 | I9: =H9*G9 -> 800 | K9: AHKRC Card Folder A/4 | L9: 0 | M9: 20 | N9: =M9*L9 -> 0
A10: Coffee (Nescafe 100 gm) Jar | B10: 1 | C10: 1954
A11: Coffee (Nescafe 200 gm) Jar | B11: =+'Grocery Items'!L9 -> 1 | C11: 3708 | D11: 3708 | F11: Harpic (450 ml) bottle | G11: =+'Janitorial Items'!N10 -> 2 | H11: 470 | I11: =H11*G11 -> 940 | K11: AHKRC Envelopes A/4 | L11: 0 | M11: 20 | N11: =M11*L11 -> 0
A12: Biscuit (Half Rolls) | B12: =+'Grocery Items'!L10 -> 0 | C12: 40 | D12: =C12*B12 -> 0 | F12: Hand Washing Soap (Large size) | G12: =+'Janitorial Items'!N12 -> 0 | H12: 128.32 | I12: =H12*G12 -> 0 | K12: AHKRC Envelopes F/5 | L12: =+'Stationery Items Stock Sheet '!L13 -> 0 | M12: 30 | N12: =M12*L12 -> 0
A13: Grand total | D13: =SUM(D5:D12) -> 39364 | F13: Dettol Hand Wash Liquid (250 ml) | G13: 6 | H13: 536 | I13: =H13*G13 -> 3216 | K13: AHKRC Envelopes L/S | L13: =+'Stationery Items Stock Sheet '!L14 -> 0 | M13: 12 | N13: =M13*L13 -> 0
F14: Sun Brite | G14: =+'Janitorial Items'!N14 -> 3 | H14: 296 | I14: =H14*G14 -> 888 | K14: Arrow Flags | L14: =+'Stationery Items Stock Sheet '!L15 -> 0 | M14: 90 | N14: =M14*L14 -> 0
F15: Lemon Max (475 ML) | G15: =+'Janitorial Items'!N15 -> 3 | H15: 251 | I15: =H15*G15 -> 753 | K15: Ball Point | L15: =+'Stationery Items Stock Sheet '!L16 -> 0 | M15: 15 | N15: =M15*L15 -> 0
F16: Wiper (Large size) | G16: =+'Janitorial Items'!N16 -> 0 | H16: 1202.01 | I16: =H16*G16 -> 0 | K16: Ball Point (Piano) | L16: =+'Stationery Items Stock Sheet '!L17 -> 10 | M16: 15 | N16: =M16*L16 -> 150
F17: Wiper for Washroom (Small size) | G17: =+'Janitorial Items'!N17 -> 0 | H17: 500 | I17: =H17*G17 -> 0 | K17: Binder clips (Large) | L17: =+'Stationery Items Stock Sheet '!L18 -> 4 | M17: 75 | N17: =M17*L17 -> 300
F18: Mop (Dry) | G18: =+'Janitorial Items'!N18 -> 0 | H18: 1151.88 | I18: =H18*G18 -> 0 | K18: Binder clips (Medium) | L18: =+'Stationery Items Stock Sheet '!L19 -> 0 | M18: 45 | N18: =M18*L18 -> 0
F19: Mop (Wet) refill | G19: =+'Janitorial Items'!N19 -> 2 | H19: 400 | I19: =H19*G19 -> 800 | K19: Binder clips (Small) | L19: =+'Stationery Items Stock Sheet '!L20 -> 0 | M19: 20 | N19: =M19*L19 -> 0
F20: Surf (500 GRM) Pkt | G20: =+'Janitorial Items'!N20 -> 2 | H20: 271 | I20: =H20*G20 -> 542 | K20: Binding Tape (2") | L20: =+'Stationery Items Stock Sheet '!L21 -> 0 | M20: 160 | N20: =M20*L20 -> 0
C21: =296+296 -> 592 | F21: Sweep Tiger Bottle | G21: =+'Janitorial Items'!N21 -> 0 | H21: 54.14 | I21: =H21*G21 -> 0 | K21: Board Eraser | L21: =+'Stationery Items Stock Sheet '!L22 -> 0 | M21: 80 | N21: =M21*L21 -> 0
F22: Glint (500 ML) | G22: =+'Janitorial Items'!N22 -> 1 | H22: 551 | I22: =H22*G22 -> 551 | K22: Board Marker | L22: =+'Stationery Items Stock Sheet '!L23 -> 0 | M22: 50 | N22: =M22*L22 -> 0
F23: Air Freshener Bottle Pack | G23: =+'Janitorial Items'!N23 -> 2 | H23: 672 | I23: =H23*G23 -> 1344 | N23: =M23*L23 -> 0
F24: Air Freshner (Air Wick) | G24: =+'Janitorial Items'!N24 -> 1 | H24: 1001.5 | I24: =H24*G24 -> 1001.5 | K24: Box File (Blue color) | L24: 2 | M24: 350 | N24: =M24*L24 -> 700
K25: Calculator (Casio)(Medium) | L25: 0 | M25: 1000 | N25: =M25*L25 -> 0
F26: Mortien Spray | G26: =+'Janitorial Items'!N25 -> 0 | H26: 1200 | I26: =H26*G26 -> 0 | K26: Calculator (Citizen) | L26: =+'Stationery Items Stock Sheet '!L26 -> 1 | M26: 800 | N26: =M26*L26 -> 800
F27: Disposable Glass | G27: =+'Janitorial Items'!N26 -> 0 | H27: 10 | I27: =H27*G27 -> 0 | K27: Carbon Paper (Pkt) | L27: =+'Stationery Items Stock Sheet '!L27 -> 0 | M27: 120 | N27: =M27*L27 -> 0
F28: Tissue Box Rose Petal Box | G28: =+'Janitorial Items'!N27 -> 8 | H28: 200 | I28: =H28*G28 -> 1600 | K28: Color Page (A/4) Pkt | L28: =+'Stationery Items Stock Sheet '!L28 -> 0 | M28: 440 | N28: =M28*L28 -> 0
F29: Toilet Roll Tissues Roll Pack each contain 10 | G29: 5 | H29: 962 | I29: =H29*G29 -> 4810 | K29: Double Tape | L29: =+'Stationery Items Stock Sheet '!L29 -> 1 | M29: 300 | N29: =M29*L29 -> 300
F30: Towel (Medium) | G30: =+'Janitorial Items'!N29 -> 0 | H30: 801 | I30: =H30*G30 -> 0 | K30: Envelopes White (A/4) | L30: =+'Stationery Items Stock Sheet '!L30 -> 0 | M30: 12 | N30: =M30*L30 -> 0
F31: Dust Bin | G31: =+'Janitorial Items'!N30 -> 0 | H31: 500 | I31: =H31*G31 -> 0 | K31: Envelopes White (A/5) | L31: =+'Stationery Items Stock Sheet '!L31 -> 0 | M31: 20 | N31: =M31*L31 -> 0
K32: Envelopes White (L/S) | L32: =+'Stationery Items Stock Sheet '!L32 -> 0 | M32: 5 | N32: =M32*L32 -> 0
F33: Garbage Bags ("22*32, 20*30, 20*24") | G33: 9 | H33: 276 | I33: 2484 | N33: =M33*L33 -> 0
F34: Dust Pan | G34: =+'Janitorial Items'!N34 -> 0 | H34: 200 | I34: =H34*G34 -> 0 | K34: Eraser | L34: =+'Stationery Items Stock Sheet '!L33 -> 0 | M34: 15 | N34: =M34*L34 -> 0
F35: Tulip Toillet Brust with Box | G35: =+'Janitorial Items'!N35 -> 1 | H35: 411 | I35: =H35*G35 -> 411 | K35: File Folder (Button Plastic) | L35: =+'Stationery Items Stock Sheet '!L34 -> 0 | M35: 20 | N35: =M35*L35 -> 0
F36: Dettol Surface Cleaner (Multi Clean) | G36: 0 | H36: 1549 | I36: -
F37: Anti Dust Broom | G37: 2 | H37: 2286 | I37: 4572
F38: Window cleaning wiper/ brush with steel handle | G38: 0 | H38: 1353.38 | I38: -
F39: Toilet Plunger | G39: =+'Janitorial Items'!N39 -> 0 | H39: 460.15 | I39: =H39*G39 -> 0
F40: Grand Total | I40: =SUM(I5:I39) -> 25312.5
K46: Highlighter Pen | L46: =+'Stationery Items Stock Sheet '!L35 -> 0 | M46: 150 | N46: =M46*L46 -> 0
...
